Workbook

Sheet Operational_Data_Entry
A1: Employee ID | B1: Employee Name | C1: Department | D1: Date | E1: Hours Worked | F1: Tasks Completed | G1: Efficiency Score | H1: Status | I1: Notes
A2: EMP0010 | B2: Daniel Thomas | C2: Finance | D2: 45566 | E2: 8.5 | F2: 10 | G2: =IFERROR(ROUND(F2/E2,2),0) | H2: =IF(E2>8.5,"Overtime",IF(E2<7,"Undertime","Normal")) | I2: Regular duties
A3: EMP0012 | B3: Joseph Jackson | C3: Marketing | D3: 45567 | E3: 7.4 | F3: 5 | G3: =IFERROR(ROUND(F3/E3,2),0) | H3: =IF(E3>8.5,"Overtime",IF(E3<7,"Undertime","Normal")) | I3: Regular duties
A4: EMP0034 | B4: John Miller | C4: Marketing | D4: 45567 | E4: 9.1 | F4: 6 | G4: =IFERROR(ROUND(F4/E4,2),0) | H4: =IF(E4>8.5,"Overtime",IF(E4<7,"Undertime","Normal"))
A5: EMP0050 | B5: David Miller | C5: HR | D5: 45568 | E5: 7.6 | F5: 5 | G5: =IFERROR(ROUND(F5/E5,2),0) | H5: =IF(E5>8.5,"Overtime",IF(E5<7,"Undertime","Normal")) | I5: Training period
A6: EMP0012 | B6: Joseph Jackson | C6: Marketing | D6: 45570 | E6: 7.9 | F6: 8 | G6: =IFERROR(ROUND(F6/E6,2),0) | H6: =IF(E6>8.5,"Overtime",IF(E6<7,"Undertime","Normal")) | I6: Training period
A7: EMP0005 | B7: James Brown | C7: Marketing | D7: 45572 | E7: 8.9 | F7: 5 | G7: =IFERROR(ROUND(F7/E7,2),0) | H7: =IF(E7>8.5,"Overtime",IF(E7<7,"Undertime","Normal")) | I7: High performance
A8: EMP0048 | B8: Daniel Miller | C8: Finance | D8: 45572 | E8: 8.1 | F8: 8 | G8: =IFERROR(ROUND(F8/E8,2),0) | H8: =IF(E8>8.5,"Overtime",IF(E8<7,"Undertime","Normal")) | I8: Training period
A9: EMP0039 | B9: Michael Martinez | C9: Marketing | D9: 45573 | E9: 9.5 | F9: 6 | G9: =IFERROR(ROUND(F9/E9,2),0) | H9: =IF(E9>8.5,"Overtime",IF(E9<7,"Undertime","Normal"))
A10: EMP0048 | B10: Daniel Miller | C10: Finance | D10: 45573 | E10: 6.9 | F10: 6 | G10: =IFERROR(ROUND(F10/E10,2),0) | H10: =IF(E10>8.5,"Overtime",IF(E10<7,"Undertime","Normal")) | I10: High performance
A11: EMP0008 | B11: Jessica Anderson | C11: Operations | D11: 45574 | E11: 6.7 | F11: 3 | G11: =IFERROR(ROUND(F11/E11,2),0) | H11: =IF(E11>8.5,"Overtime",IF(E11<7,"Undertime","Normal")) | I11: Project deadline
A12: EMP0043 | B12: Nancy Wilson | C12: Marketing | D12: 45575 | E12: 6.7 | F12: 8 | G12: =IFERROR(ROUND(F12/E12,2),0) | H12: =IF(E12>8.5,"Overtime",IF(E12<7,"Undertime","Normal")) | I12: On schedule
A13: EMP0043 | B13: Nancy Wilson | C13: Marketing | D13: 45578 | E13: 9.9 | F13: 15 | G13: =IFERROR(ROUND(F13/E13,2),0) | H13: =IF(E13>8.5,"Overtime",IF(E13<7,"Undertime","Normal")) | I13: On schedule
A14: EMP0020 | B14: John Moore | C14: Operations | D14: 45579 | E14: 8.9 | F14: 9 | G14: =IFERROR(ROUND(F14/E14,2),0) | H14: =IF(E14>8.5,"Overtime",IF(E14<7,"Undertime","Normal"))
A15: EMP0045 | B15: Michael Thompson | C15: Sales | D15: 45579 | E15: 9.4 | F15: 11 | G15: =IFERROR(ROUND(F15/E15,2),0) | H15: =IF(E15>8.5,"Overtime",IF(E15<7,"Undertime","Normal"))
A16: EMP0015 | B16: Jessica White | C16: Marketing | D16: 45581 | E16: 7.2 | F16: 3 | G16: =IFERROR(ROUND(F16/E16,2),0) | H16: =IF(E16>8.5,"Overtime",IF(E16<7,"Undertime","Normal")) | I16: Regular duties
A17: EMP0026 | B17: Thomas Thompson | C17: Finance | D17: 45581 | E17: 9.1 | F17: 9 | G17: =IFERROR(ROUND(F17/E17,2),0) | H17: =IF(E17>8.5,"Overtime",IF(E17<7,"Undertime","Normal")) | I17: Regular duties
A18: EMP0023 | B18: Betty Rodriguez | C18: Finance | D18: 45583 | E18: 7.2 | F18: 10 | G18: =IFERROR(ROUND(F18/E18,2),0) | H18: =IF(E18>8.5,"Overtime",IF(E18<7,"Undertime","Normal")) | I18: Training period
A19: EMP0019 | B19: Robert Wilson | C19: Operations | D19: 45584 | E19: 7.6 | F19: 8 | G19: =IFERROR(ROUND(F19/E19,2),0) | H19: =IF(E19>8.5,"Overtime",IF(E19<7,"Undertime","Normal")) | I19: Training period
A20: EMP0031 | B20: Jennifer Garcia | C20: Finance | D20: 45584 | E20: 9 | F20: 4 | G20: =IFERROR(ROUND(F20/E20,2),0) | H20: =IF(E20>8.5,"Overtime",IF(E20<7,"Undertime","Normal")) | I20: High performance
A21: EMP0006 | B21: William Wilson | C21: HR | D21: 45585 | E21: 9.4 | F21: 8 | G21: =IFERROR(ROUND(F21/E21,2),0) | H21: =IF(E21>8.5,"Overtime",IF(E21<7,"Undertime","Normal")) | I21: High performance
A22: EMP0041 | B22: Jessica Anderson | C22: Sales | D22: 45586 | E22: 8 | F22: 14 | G22: =IFERROR(ROUND(F22/E22,2),0) | H22: =IF(E22>8.5,"Overtime",IF(E22<7,"Undertime","Normal")) | I22: On schedule
A23: EMP0036 | B23: Sarah Jackson | C23: Marketing | D23: 45588 | E23: 8 | F23: 12 | G23: =IFERROR(ROUND(F23/E23,2),0) | H23: =IF(E23>8.5,"Overtime",IF(E23<7,"Undertime","Normal")) | I23: Regular duties
A24: EMP0002 | B24: Robert Moore | C24: Marketing | D24: 45589 | E24: 7.3 | F24: 3 | G24: =IFERROR(ROUND(F24/E24,2),0) | H24: =IF(E24>8.5,"Overtime",IF(E24<7,"Undertime","Normal")) | I24: Project deadline
A25: EMP0017 | B25: John Miller | C25: IT | D25: 45589 | E25: 7.4 | F25: 10 | G25: =IFERROR(ROUND(F25/E25,2),0) | H25: =IF(E25>8.5,"Overtime",IF(E25<7,"Undertime","Normal")) | I25: On schedule
A26: EMP0043 | B26: Nancy Wilson | C26: Marketing | D26: 45589 | E26: 10 | F26: 13 | G26: =IFERROR(ROUND(F26/E26,2),0) | H26: =IF(E26>8.5,"Overtime",IF(E26<7,"Undertime","Normal")) | I26: On schedule
A27: EMP0013 | B27: Patricia Martinez | C27: Sales | D27: 45593 | E27: 6.5 | F27: 8 | G27: =IFERROR(ROUND(F27/E27,2),0) | H27: =IF(E27>8.5,"Overtime",IF(E27<7,"Undertime","Normal")) | I27: Regular duties
... A31: EMP0025 | B31: William Garcia | C31: Sales | D31: 45596 | E31: 7 | F31: 14 | G31: =IFERROR(ROUND(F31/E31,2),0) | H31: =IF(E31>8.5,"Overtime",IF(E31<7,"Undertime","Normal")) | I31: High performance
A32: EMP0048 | B32: Daniel Miller | C32: Finance | D32: 45596 | E32: 7.6 | F32: 5 | G32: =IFERROR(ROUND(F32/E32,2),0) | H32: =IF(E32>8.5,"Overtime",IF(E32<7,"Undertime","Normal"))
A33: EMP0005 | B33: James Brown | C33: Marketing | D33: 45597 | E33: 8.4 | F33: 15 | G33: =IFERROR(ROUND(F33/E33,2),0) | H33: =IF(E33>8.5,"Overtime",IF(E33<7,"Undertime","Normal")) | I33: Regular duties
A34: EMP0008 | B34: Jessica Anderson | C34: Operations | D34: 45597 | E34: 8.8 | F34: 15 | G34: =IFERROR(ROUND(F34/E34,2),0) | H34: =IF(E34>8.5,"Overtime",IF(E34<7,"Undertime","Normal")) | I34: Project deadline
A35: EMP0024 | B35: Nancy Thompson | C35: Marketing | D35: 45597 | E35: 9.8 | F35: 13 | G35: =IFERROR(ROUND(F35/E35,2),0) | H35: =IF(E35>8.5,"Overtime",IF(E35<7,"Undertime","Normal"))
A36: EMP0036 | B36: Sarah Jackson | C36: Marketing | D36: 45598 | E36: 6.7 | F36: 9 | G36: =IFERROR(ROUND(F36/E36,2),0) | H36: =IF(E36>8.5,"Overtime",IF(E36<7,"Undertime","Normal")) | I36: High performance
A37: EMP0013 | B37: Patricia Martinez | C37: Sales | D37: 45599 | E37: 6.7 | F37: 3 | G37: =IFERROR(ROUND(F37/E37,2),0) | H37: =IF(E37>8.5,"Overtime",IF(E37<7,"Undertime","Normal"))
A38: EMP0017 | B38: John Miller | C38: IT | D38: 45599 | E38: 9.7 | F38: 10 | G38: =IFERROR(ROUND(F38/E38,2),0) | H38: =IF(E38>8.5,"Overtime",IF(E38<7,"Undertime","Normal")) | I38: On schedule
A39: EMP0007 | B39: Linda Wilson | C39: Operations | D39: 45600 | E39: 8 | F39: 7 | G39: =IFERROR(ROUND(F39/E39,2),0) | H39: =IF(E39>8.5,"Overtime",IF(E39<7,"Undertime","Normal")) | I39: Project deadline
A40: EMP0020 | B40: John Moore | C40: Operations | D40: 45602 | E40: 10 | F40: 6 | G40: =IFERROR(ROUND(F40/E40,2),0) | H40: =IF(E40>8.5,"Overtime",IF(E40<7,"Undertime","Normal"))
A41: EMP0024 | B41: Nancy Thompson | C41: Marketing | D41: 45602 | E41: 6.5 | F41: 3 | G41: =IFERROR(ROUND(F41/E41,2),0) | H41: =IF(E41>8.5,"Overtime",IF(E41<7,"Undertime","Normal")) | I41: Project deadline
A42: EMP0024 | B42: Nancy Thompson | C42: Marketing | D42: 45602 | E42: 7.4 | F42: 5 | G42: =IFERROR(ROUND(F42/E42,2),0) | H42: =IF(E42>8.5,"Overtime",IF(E42<7,"Undertime","Normal")) | I42: Project deadline
A43: EMP0027 | B43: Susan Taylor | C43: Sales | D43: 45604 | E43: 8.3 | F43: 13 | G43: =IFERROR(ROUND(F43/E43,2),0) | H43: =IF(E43>8.5,"Overtime",IF(E43<7,"Undertime","Normal")) | I43: On schedule
...

Sheet Operational_Summary
A1: Department | B1: Total Employees | C1: Total Hours | D1: Avg Hours/Employee | E1: Total Tasks | F1: Avg Tasks/Employee | G1: Avg Efficiency | H1: First Employee | I1: First Employee Hours | J1: Dynamic Range Sum
A2: Sales | B2: =SUMPRODUCT((Operational_Data_Entry!$C$2:$C$110=A2)/COUNTIFS(Operational_Data_Entry!$C$2:$C$110,Operational_Data_Entry!$C$2:$C$110,Operational_Data_Entry!$B$2:$B$110,Operational_Data_Entry!$B$2:$B$110)) | C2: =SUMIFS(Operational_Data_Entry!$E$2:$E$110,Operational_Data_Entry!$C$2:$C$110,A2) | D2: =IFERROR(C2/B2,0) | E2: =SUMIFS(Operational_Data_Entry!$F$2:$F$110,Operational_Data_Entry!$C$2:$C$110,A2) | F2: =IFERROR(E2/B2,0) | G2: =AVERAGEIFS(Operational_Data_Entry!$G$2:$G$110,Operational_Data_Entry!$C$2:$C$110,A2) | H2: =IFERROR(INDEX(Operational_Data_Entry!$B$2:$B$110,MATCH(A2,Operational_Data_Entry!$C$2:$C$110,0)),"-") | I2: =IFERROR(INDEX(Operational_Data_Entry!$E$2:$E$110,MATCH(A2,Operational_Data_Entry!$C$2:$C$110,0)),0) | J2: =IFERROR(SUM(OFFSET(Operational_Data_Entry!$E$2,MATCH(A2,Operational_Data_Entry!$C$2:$C$110,0)-1,0,5,1)),0)
A3: Marketing | B3: =SUMPRODUCT((Operational_Data_Entry!$C$2:$C$110=A3)/COUNTIFS(Operational_Data_Entry!$C$2:$C$110,Operational_Data_Entry!$C$2:$C$110,Operational_Data_Entry!$B$2:$B$110,Operational_Data_Entry!$B$2:$B$110)) | C3: =SUMIFS(Operational_Data_Entry!$E$2:$E$110,Operational_Data_Entry!$C$2:$C$110,A3) | D3: =IFERROR(C3/B3,0) | E3: =SUMIFS(Operational_Data_Entry!$F$2:$F$110,Operational_Data_Entry!$C$2:$C$110,A3) | F3: =IFERROR(E3/B3,0) | G3: =AVERAGEIFS(Operational_Data_Entry!$G$2:$G$110,Operational_Data_Entry!$C$2:$C$110,A3) | H3: =IFERROR(INDEX(Operational_Data_Entry!$B$2:$B$110,MATCH(A3,Operational_Data_Entry!$C$2:$C$110,0)),"-") | I3: =IFERROR(INDEX(Operational_Data_Entry!$E$2:$E$110,MATCH(A3,Operational_Data_Entry!$C$2:$C$110,0)),0) | J3: =IFERROR(SUM(OFFSET(Operational_Data_Entry!$E$2,MATCH(A3,Operational_Data_Entry!$C$2:$C$110,0)-1,0,5,1)),0)
A4: Operations | B4: =SUMPRODUCT((Operational_Data_Entry!$C$2:$C$110=A4)/COUNTIFS(Operational_Data_Entry!$C$2:$C$110,Operational_Data_Entry!$C$2:$C$110,Operational_Data_Entry!$B$2:$B$110,Operational_Data_Entry!$B$2:$B$110)) | C4: =SUMIFS(Operational_Data_Entry!$E$2:$E$110,Operational_Data_Entry!$C$2:$C$110,A4) | D4: =IFERROR(C4/B4,0) | E4: =SUMIFS(Operational_Data_Entry!$F$2:$F$110,Operational_Data_Entry!$C$2:$C$110,A4) | F4: =IFERROR(E4/B4,0) | G4: =AVERAGEIFS(Operational_Data_Entry!$G$2:$G$110,Operational_Data_Entry!$C$2:$C$110,A4) | H4: =IFERROR(INDEX(Operational_Data_Entry!$B$2:$B$110,MATCH(A4,Operational_Data_Entry!$C$2:$C$110,0)),"-") | I4: =IFERROR(INDEX(Operational_Data_Entry!$E$2:$E$110,MATCH(A4,Operational_Data_Entry!$C$2:$C$110,0)),0) | J4: =IFERROR(SUM(OFFSET(Operational_Data_Entry!$E$2,MATCH(A4,Operational_Data_Entry!$C$2:$C$110,0)-1,0,5,1)),0)
A5: Finance | B5: =SUMPRODUCT((Operational_Data_Entry!$C$2:$C$110=A5)/COUNTIFS(Operational_Data_Entry!$C$2:$C$110,Operational_Data_Entry!$C$2:$C$110,Operational_Data_Entry!$B$2:$B$110,Operational_Data_Entry!$B$2:$B$110)) | C5: =SUMIFS(Operational_Data_Entry!$E$2:$E$110,Operational_Data_Entry!$C$2:$C$110,A5) | D5: =IFERROR(C5/B5,0) | E5: =SUMIFS(Operational_Data_Entry!$F$2:$F$110,Operational_Data_Entry!$C$2:$C$110,A5) | F5: =IFERROR(E5/B5,0) | G5: =AVERAGEIFS(Operational_Data_Entry!$G$2:$G$110,Operational_Data_Entry!$C$2:$C$110,A5) | H5: =IFERROR(INDEX(Operational_Data_Entry!$B$2:$B$110,MATCH(A5,Operational_Data_Entry!$C$2:$C$110,0)),"-") | I5: =IFERROR(INDEX(Operational_Data_Entry!$E$2:$E$110,MATCH(A5,Operational_Data_Entry!$C$2:$C$110,0)),0) | J5: =IFERROR(SUM(OFFSET(Operational_Data_Entry!$E$2,MATCH(A5,Operational_Data_Entry!$C$2:$C$110,0)-1,0,5,1)),0)
A6: IT | B6: =SUMPRODUCT((Operational_Data_Entry!$C$2:$C$110=A6)/COUNTIFS(Operational_Data_Entry!$C$2:$C$110,Operational_Data_Entry!$C$2:$C$110,Operational_Data_Entry!$B$2:$B$110,Operational_Data_Entry!$B$2:$B$110)) | C6: =SUMIFS(Operational_Data_Entry!$E$2:$E$110,Operational_Data_Entry!$C$2:$C$110,A6) | D6: =IFERROR(C6/B6,0) | E6: =SUMIFS(Operational_Data_Entry!$F$2:$F$110,Operational_Data_Entry!$C$2:$C$110,A6) | F6: =IFERROR(E6/B6,0) | G6: =AVERAGEIFS(Operational_Data_Entry!$G$2:$G$110,Operational_Data_Entry!$C$2:$C$110,A6) | H6: =IFERROR(INDEX(Operational_Data_Entry!$B$2:$B$110,MATCH(A6,Operational_Data_Entry!$C$2:$C$110,0)),"-") | I6: =IFERROR(INDEX(Operational_Data_Entry!$E$2:$E$110,MATCH(A6,Operational_Data_Entry!$C$2:$C$110,0)),0) | J6: =IFERROR(SUM(OFFSET(Operational_Data_Entry!$E$2,MATCH(A6,Operational_Data_Entry!$C$2:$C$110,0)-1,0,5,1)),0)
A7: HR | B7: =SUMPRODUCT((Operational_Data_Entry!$C$2:$C$110=A7)/COUNTIFS(Operational_Data_Entry!$C$2:$C$110,Operational_Data_Entry!$C$2:$C$110,Operational_Data_Entry!$B$2:$B$110,Operational_Data_Entry!$B$2:$B$110)) | C7: =SUMIFS(Operational_Data_Entry!$E$2:$E$110,Operational_Data_Entry!$C$2:$C$110,A7) | D7: =IFERROR(C7/B7,0) | E7: =SUMIFS(Operational_Data_Entry!$F$2:$F$110,Operational_Data_Entry!$C$2:$C$110,A7) | F7: =IFERROR(E7/B7,0) | G7: =AVERAGEIFS(Operational_Data_Entry!$G$2:$G$110,Operational_Data_Entry!$C$2:$C$110,A7) | H7: =IFERROR(INDEX(Operational_Data_Entry!$B$2:$B$110,MATCH(A7,Operational_Data_Entry!$C$2:$C$110,0)),"-") | I7: =IFERROR(INDEX(Operational_Data_Entry!$E$2:$E$110,MATCH(A7,Operational_Data_Entry!$C$2:$C$110,0)),0) | J7: =IFERROR(SUM(OFFSET(Operational_Data_Entry!$E$2,MATCH(A7,Operational_Data_Entry!$C$2:$C$110,0)-1,0,5,1)),0)

Sheet Pivot_Operational
A1: PIVOTTABLE PLACEHOLDER
A3: Instructions:
A4: 1. Select any cell in the 'Operational_Data_Entry' sheet
A5: 2. Go to Insert > PivotTable
A6: 3. Place the PivotTable in this sheet
A7: 4. Recommended configuration:
A8: - Rows: Department, Employee Name
A9: - Values: Sum of Hours Worked, Average of Efficiency Score
A10: - Filters: Date, Status

Sheet Transaction_Records
A1: Transaction ID | B1: Date | C1: Department | D1: Transaction Type | E1: Amount | F1: Status | G1: Approved By | H1: Employee ID | I1: Description | J1: Payment Method
A2: TXN00005 | B2: 45566 | C2: HR | D2: Invoice | E2: 16574.33 | F2: Completed | G2: Sarah Davis | H2: EMP0018 | I2: Invoice for project materials | J2: Credit Card
A3: TXN00037 | B3: 45566 | C3: Marketing | D3: Payment | E3: 26991.84 | F3: Pending | G3: Jennifer Martinez | H3: EMP0001 | I3: Client payment | J3: Check
A4: TXN00011 | B4: 45568 | C4: Marketing | D4: Payment | E4: 24989.88 | F4: Completed | G4: John Davis | H4: EMP0012 | I4: Client payment | J4: Bank Transfer
A5: TXN00050 | B5: 45568 | C5: Finance | D5: Invoice | E5: 37157.71 | F5: Completed | G5: David Rodriguez | H5: EMP0010 | I5: Q4 invoice processing | J5: Credit Card
A6: TXN00023 | B6: 45569 | C6: Sales | D6: Payment | E6: 6229.51 | F6: Completed | G6: Joseph Thompson | H6: EMP0016 | I6: Sales department payment | J6: Credit Card
A7: TXN00025 | B7: 45570 | C7: Operations | D7: Refund | E7: 4923.89 | F7: Completed | G7: Daniel Rodriguez | H7: EMP0043 | I7: Vendor refund | J7: Check
A8: TXN00043 | B8: 45570 | C8: Marketing | D8: Purchase Order | E8: 23346.33 | F8: Pending | G8: Barbara Harris | H8: EMP0044 | I8: Purchase Order for project materials | J8: Credit Card
A9: TXN00053 | B9: 45570 | C9: Finance | D9: Refund | E9: 2104.82 | F9: Pending | G9: Robert Martin | H9: EMP0030 | I9: Refund for project materials | J9: Credit Card
A10: TXN00095 | B10: 45571 | C10: IT | D10: Expense Claim | E10: 1830.46 | F10: Completed | G10: Karen Taylor | H10: EMP0010 | I10: Q4 expense claim processing | J10: Check
A11: TXN00042 | B11: 45572 | C11: HR | D11: Payment | E11: 29996.72 | F11: Cancelled | G11: William Wilson | H11: EMP0019 | I11: HR department payment | J11: ACH
A12: TXN00088 | B12: 45572 | C12: Sales | D12: Invoice | E12: 16585.77 | F12: Completed | G12: Charles White | H12: EMP0017 | I12: Q4 invoice processing | J12: Credit Card
A13: TXN00041 | B13: 45573 | C13: Finance | D13: Payment | E13: 29689.61 | F13: Pending | G13: Thomas Thomas | H13: EMP0036 | I13: Vendor payment | J13: Bank Transfer
... A101: TXN00001 | B101: 45653 | C101: Marketing | D101: Refund | E101: 3788.74 | F101: Completed | G101: Jennifer Moore | H101: EMP0012 | I101: Marketing department refund | J101: Credit Card

Sheet Transaction_Summary
A1: Department | B1: Total Transactions | C1: Completed | D1: Pending | E1: Cancelled | F1: Total Amount | G1: Avg Transaction | H1: Max Transaction | I1: First Trans ID | J1: First Trans Amount | K1: Dynamic Offset Sum
A2: Sales | B2: =COUNTIF(Transaction_Records!$C$2:$C$101,A2) | C2: =COUNTIFS(Transaction_Records!$C$2:$C$101,A2,Transaction_Records!$F$2:$F$101,"Completed") | D2: =COUNTIFS(Transaction_Records!$C$2:$C$101,A2,Transaction_Records!$F$2:$F$101,"Pending") | E2: =COUNTIFS(Transaction_Records!$C$2:$C$101,A2,Transaction_Records!$F$2:$F$101,"Cancelled") | F2: =SUMIF(Transaction_Records!$C$2:$C$101,A2,Transaction_Records!$E$2:$E$101) | G2: =AVERAGEIF(Transaction_Records!$C$2:$C$101,A2,Transaction_Records!$E$2:$E$101) | H2: =IFERROR(MAX(IF(Transaction_Records!$C$2:$C$101=A2,Transaction_Records!$E$2:$E$101)),0) | I2: =IFERROR(INDEX(Transaction_Records!$A$2:$A$101,MATCH(A2,Transaction_Records!$C$2:$C$101,0)),"-") | J2: =IFERROR(INDEX(Transaction_Records!$E$2:$E$101,MATCH(A2,Transaction_Records!$C$2:$C$101,0)),0) | K2: =IFERROR(SUM(OFFSET(Transaction_Records!$E$2,MATCH(A2,Transaction_Records!$C$2:$C$101,0)-1,0,10,1)),0)
A3: Marketing | B3: =COUNTIF(Transaction_Records!$C$2:$C$101,A3) | C3: =COUNTIFS(Transaction_Records!$C$2:$C$101,A3,Transaction_Records!$F$2:$F$101,"Completed") | D3: =COUNTIFS(Transaction_Records!$C$2:$C$101,A3,Transaction_Records!$F$2:$F$101,"Pending") | E3: =COUNTIFS(Transaction_Records!$C$2:$C$101,A3,Transaction_Records!$F$2:$F$101,"Cancelled") | F3: =SUMIF(Transaction_Records!$C$2:$C$101,A3,Transaction_Records!$E$2:$E$101) | G3: =AVERAGEIF(Transaction_Records!$C$2:$C$101,A3,Transaction_Records!$E$2:$E$101) | H3: =IFERROR(MAX(IF(Transaction_Records!$C$2:$C$101=A3,Transaction_Records!$E$2:$E$101)),0) | I3: =IFERROR(INDEX(Transaction_Records!$A$2:$A$101,MATCH(A3,Transaction_Records!$C$2:$C$101,0)),"-") | J3: =IFERROR(INDEX(Transaction_Records!$E$2:$E$101,MATCH(A3,Transaction_Records!$C$2:$C$101,0)),0) | K3: =IFERROR(SUM(OFFSET(Transaction_Records!$E$2,MATCH(A3,Transaction_Records!$C$2:$C$101,0)-1,0,10,1)),0)
A4: Operations | B4: =COUNTIF(Transaction_Records!$C$2:$C$101,A4) | C4: =COUNTIFS(Transaction_Records!$C$2:$C$101,A4,Transaction_Records!$F$2:$F$101,"Completed") | D4: =COUNTIFS(Transaction_Records!$C$2:$C$101,A4,Transaction_Records!$F$2:$F$101,"Pending") | E4: =COUNTIFS(Transaction_Records!$C$2:$C$101,A4,Transaction_Records!$F$2:$F$101,"Cancelled") | F4: =SUMIF(Transaction_Records!$C$2:$C$101,A4,Transaction_Records!$E$2:$E$101) | G4: =AVERAGEIF(Transaction_Records!$C$2:$C$101,A4,Transaction_Records!$E$2:$E$101) | H4: =IFERROR(MAX(IF(Transaction_Records!$C$2:$C$101=A4,Transaction_Records!$E$2:$E$101)),0) | I4: =IFERROR(INDEX(Transaction_Records!$A$2:$A$101,MATCH(A4,Transaction_Records!$C$2:$C$101,0)),"-") | J4: =IFERROR(INDEX(Transaction_Records!$E$2:$E$101,MATCH(A4,Transaction_Records!$C$2:$C$101,0)),0) | K4: =IFERROR(SUM(OFFSET(Transaction_Records!$E$2,MATCH(A4,Transaction_Records!$C$2:$C$101,0)-1,0,10,1)),0)
A5: Finance | B5: =COUNTIF(Transaction_Records!$C$2:$C$101,A5) | C5: =COUNTIFS(Transaction_Records!$C$2:$C$101,A5,Transaction_Records!$F$2:$F$101,"Completed") | D5: =COUNTIFS(Transaction_Records!$C$2:$C$101,A5,Transaction_Records!$F$2:$F$101,"Pending") | E5: =COUNTIFS(Transaction_Records!$C$2:$C$101,A5,Transaction_Records!$F$2:$F$101,"Cancelled") | F5: =SUMIF(Transaction_Records!$C$2:$C$101,A5,Transaction_Records!$E$2:$E$101) | G5: =AVERAGEIF(Transaction_Records!$C$2:$C$101,A5,Transaction_Records!$E$2:$E$101) | H5: =IFERROR(MAX(IF(Transaction_Records!$C$2:$C$101=A5,Transaction_Records!$E$2:$E$101)),0) | I5: =IFERROR(INDEX(Transaction_Records!$A$2:$A$101,MATCH(A5,Transaction_Records!$C$2:$C$101,0)),"-") | J5: =IFERROR(INDEX(Transaction_Records!$E$2:$E$101,MATCH(A5,Transaction_Records!$C$2:$C$101,0)),0) | K5: =IFERROR(SUM(OFFSET(Transaction_Records!$E$2,MATCH(A5,Transaction_Records!$C$2:$C$101,0)-1,0,10,1)),0)
A6: IT | B6: =COUNTIF(Transaction_Records!$C$2:$C$101,A6) | C6: =COUNTIFS(Transaction_Records!$C$2:$C$101,A6,Transaction_Records!$F$2:$F$101,"Completed") | D6: =COUNTIFS(Transaction_Records!$C$2:$C$101,A6,Transaction_Records!$F$2:$F$101,"Pending") | E6: =COUNTIFS(Transaction_Records!$C$2:$C$101,A6,Transaction_Records!$F$2:$F$101,"Cancelled") | F6: =SUMIF(Transaction_Records!$C$2:$C$101,A6,Transaction_Records!$E$2:$E$101) | G6: =AVERAGEIF(Transaction_Records!$C$2:$C$101,A6,Transaction_Records!$E$2:$E$101) | H6: =IFERROR(MAX(IF(Transaction_Records!$C$2:$C$101=A6,Transaction_Records!$E$2:$E$101)),0) | I6: =IFERROR(INDEX(Transaction_Records!$A$2:$A$101,MATCH(A6,Transaction_Records!$C$2:$C$101,0)),"-") | J6: =IFERROR(INDEX(Transaction_Records!$E$2:$E$101,MATCH(A6,Transaction_Records!$C$2:$C$101,0)),0) | K6: =IFERROR(SUM(OFFSET(Transaction_Records!$E$2,MATCH(A6,Transaction_Records!$C$2:$C$101,0)-1,0,10,1)),0)
A7: HR | B7: =COUNTIF(Transaction_Records!$C$2:$C$101,A7) | C7: =COUNTIFS(Transaction_Records!$C$2:$C$101,A7,Transaction_Records!$F$2:$F$101,"Completed") | D7: =COUNTIFS(Transaction_Records!$C$2:$C$101,A7,Transaction_Records!$F$2:$F$101,"Pending") | E7: =COUNTIFS(Transaction_Records!$C$2:$C$101,A7,Transaction_Records!$F$2:$F$101,"Cancelled") | F7: =SUMIF(Transaction_Records!$C$2:$C$101,A7,Transaction_Records!$E$2:$E$101) | G7: =AVERAGEIF(Transaction_Records!$C$2:$C$101,A7,Transaction_Records!$E$2:$E$101) | H7: =IFERROR(MAX(IF(Transaction_Records!$C$2:$C$101=A7,Transaction_Records!$E$2:$E$101)),0) | I7: =IFERROR(INDEX(Transaction_Records!$A$2:$A$101,MATCH(A7,Transaction_Records!$C$2:$C$101,0)),"-") | J7: =IFERROR(INDEX(Transaction_Records!$E$2:$E$101,MATCH(A7,Transaction_Records!$C$2:$C$101,0)),0) | K7: =IFERROR(SUM(OFFSET(Transaction_Records!$E$2,MATCH(A7,Transaction_Records!$C$2:$C$101,0)-1,0,10,1)),0)

Sheet Pivot_Transactions
A1: PIVOTTABLE PLACEHOLDER
A3: Instructions:
A4: 1. Select any cell in the 'Transaction_Records' sheet
A5: 2. Go to Insert > PivotTable
A6: 3. Place the PivotTable in this sheet
A7: 4. Recommended configuration:
A8: - Rows: Department, Transaction Type
A9: - Values: Sum of Amount, Count of Transaction ID
A10: - Filters: Status, Date
A11: 5. Consider adding a PivotChart for visual analysis
